Workbook

Sheet Organization
A1: 节点名称 | B1: 节点代号 | C1: 上级节点 | D1: 节点负责人 | E1: 节点所在级 | F1: 公司代码 | G1: 成本中心
A2: CEO | B2: 10 | D2: Ximing.Huang | E2: 1 | F2: 2000 | G2: 2000001000
A3: 总裁办公室 | B3: 10-20 | C3: 10 | D3: Ximing.Huang | E3: 2 | F3: 2000 | G3: 2000002000
A4: 总裁办公室 | B4: 10-20-10 | C4: 10-20 | D4: Ximing.Huang | E4: 3 | F4: 2000 | G4: 2000002000
A5: 公司管理中心 | B5: 10-10 | C5: 10 | D5: Xueli.Sun | E5: 2 | F5: 2000 | G5: 2000003000
A6: 财务部 | B6: 10-11 | C6: 10 | D6: Ximing.Huang | E6: 2 | F6: 2000 | G6: 2000004000
A7: 信息技术管理中心 | B7: 10-12 | C7: 10 | D7: Bing.Xu | E7: 2 | F7: 2000 | G7: 2000005000
A8: 市场营销管理中心 | B8: 10-13 | C8: 10 | D8: Tian.Zhang | E8: 2 | F8: 2000 | G8: 2000006000
A9: 供应链 | B9: 10-14 | C9: 10 | D9: Hu.Liang | E9: 2 | F9: 2000 | G9: 2000007000
A10: 质量管理中心 | B10: 10-15 | C10: 10 | D10: Song.Yue | E10: 2 | F10: 2000 | G10: 2000008000
A11: 生产制造中心 | B11: 10-16 | C11: 10 | D11: Steven.Remstad | E11: 2 | F11: 2000 | G11: 2000009000
A12: 盛和电池 | B12: 10-17 | C12: 10 | D12: Zhiwei.Zhang | E12: 2 | F12: 3000 | G12: 3000010000
A13: 上海研发中心 | B13: 10-18 | C13: 10 | D13: Bin.Du | E13: 2 | F13: 2000 | G13: 2000011000
A14: 北美研发中心 | B14: 10-19 | C14: 10 | D14: Ken.Weise | E14: 2 | F14: 5000 | G14: 5000012000
A15: 人力资源部 | B15: 10-10-10 | C15: 10-10 | D15: Huixian.Liu | E15: 3 | F15: 2000 | G15: 2000003001
A16: 行政管理部 | B16: 10-10-11 | C16: 10-10 | D16: Huixian.Liu | E16: 3 | F16: 2000 | G16: 2000003002
A17: 发展规划部 | B17: 10-10-12 | C17: 10-10 | D17: Xueli.Sun | E17: 3 | F17: 2000 | G17: 2000003003
A18: 法务部 | B18: 10-10-13 | C18: 10-10 | D18: Xueli.Sun | E18: 3 | F18: 2000 | G18: 2000003004
A19: 财务会计 | B19: 10-11-10 | C19: 10-11 | D19: Xiaoli.Zheng | E19: 3 | F19: 2000 | G19: 2000004001
A20: 项目财务 | B20: 10-11-11 | C20: 10-11 | D20: Xiaoli.Zheng | E20: 3 | F20: 2000 | G20: 2000004002
A21: 市场财务 | B21: 10-11-12 | C21: 10-11 | D21: Xiaoli.Zheng | E21: 3 | F21: 2000 | G21: 2000004003
A22: 生产财务 | B22: 10-11-13 | C22: 10-11 | D22: Xiaoli.Zheng | E22: 3 | F22: 2000 | G22: 2000004004
A23: 市场/营销部 | B23: 10-12-10 | C23: 10-12 | D23: Bing.Xu | E23: 3 | F23: 2000 | G23: 2000005001
A24: 设计/生产/供应链 | B24: 10-12-11 | C24: 10-12 | D24: Jianzhao.Liu | E24: 3 | F24: 2000 | G24: 2000005002
A25: 办公自动化/信息安全系统部 | B25: 10-12-12 | C25: 10-12 | D25: Zhiyong.Wen | E25: 3 | F25: 2000 | G25: 2000005003
A26: 大数据/车联网部 | B26: 10-12-13 | C26: 10-12 | D26: Bing.Xu | E26: 3 | F26: 2000 | G26: 2000005004
... A46: 质量管理 | B46: 10-17-12 | C46: 10-17 | D46: Zhiwei.Zhang | E46: 3 | F46: 3000 | G46: 3000010003
A47: 财务 | B47: 10-17-13 | C47: 10-17 | D47: Zhiwei.Zhang | E47: 3 | F47: 2000 | G47: 2000004000
A48: 人力资源 | B48: 10-17-14 | C48: 10-17 | D48: Yongle.Jia | E48: 3 | F48: 3000 | G48: 3000010004
A49: 行政/IT | B49: 10-17-15 | C49: 10-17 | D49: Zhiwei.Zhang | E49: 3 | F49: 3000 | G49: 3000010005
A50: 整车集成 | B50: 10-18-10 | C50: 10-18 | D50: Ying.Li | E50: 3 | F50: 2000 | G50: 2000011001
A51: 动力总成 | B51: 10-18-11 | C51: 10-18 | D51: Zhiwei.Zhang | E51: 3 | F51: 2000 | G51: 2000011002
A52: 电子电器 | B52: 10-18-12 | C52: 10-18 | D52: John.Kook | E52: 3 | F52: 2000 | G52: 2000011003
A53: 车身工程 | B53: 10-18-13 | C53: 10-18 | D53: HyungJin.Kim | E53: 3 | F53: 2000 | G53: 2000011004
A54: 车辆性能及底盘设计 | B54: 10-18-14 | C54: 10-18 | D54: Yimin.Bao | E54: 3 | F54: 2000 | G54: 2000011000
A55: 安全/材料/轻盈化 | B55: 10-18-15 | C55: 10-18 | D55: Keming.Chen | E55: 3 | F55: 2000 | G55: 2000011006
A56: 试制试验 | B56: 10-18-16 | C56: 10-18 | D56: Bin.Du | E56: 3 | F56: 2000 | G56: 2000009007
A57: 车身工程 | B57: 10-19-10 | C57: 10-19 | D57: Yehia.Harajli | E57: 3 | F57: 2000 | G57: 2000011004
A58: 底盘工程 | B58: 10-19-11 | C58: 10-19 | D58: Anthony.Marcheff | E58: 3 | F58: 5000 | G58: 5000012002
A59: 总布置 | B59: 10-19-12 | C59: 10-19 | D59: Aaron.Smith | E59: 3 | F59: 5000 | G59: 5000012003
...

Sheet Sheet1
A1: 序号 | B1: 工号 | C1: 中文名 | D1: 英文 | E1: 英文 | G1: 中心 | H1: 部 | I1: 成本中心
A2: 1 | B2: E00001 | C2: 黄希鸣 | D2: Ximing.Huang | E2: HUANG XIMING | F2: =VLOOKUP(D2,Sheet2!$B$1:$B$558,1,FALSE) -> Ximing.Huang | G2: 总裁办公室
A3: 2 | B3: E00002 | C3: 孙雪莉 | D3: xueli.sun | E3: SUN XUELI | F3: =VLOOKUP(D3,Sheet2!$B$1:$B$558,1,FALSE) -> xueli.sun | G3: 公司管理中心 | H3: -
A4: 3 | B4: E00003 | C4: 张天 | D4: tian.zhang | E4: ZHANG TIAN | F4: =VLOOKUP(D4,Sheet2!$B$1:$B$558,1,FALSE) -> Tian.Zhang | G4: 市场营销管理中心 | H4: -
A5: 4 | B5: E00004 | C5: 张志伟 | D5: zhiwei.zhang | E5: ZHANG ZHIWEI | F5: =VLOOKUP(D5,Sheet2!$B$1:$B$558,1,FALSE) -> zhiwei.zhang | G5: 上海研发中心 | H5: 动力总成
A6: 5 | B6: E00005 | C6: 杜彬 | D6: bin.du | E6: DU BIN | F6: =VLOOKUP(D6,Sheet2!$B$1:$B$558,1,FALSE) -> bin.du | G6: 上海研发中心 | H6: -
A7: 6 | B7: E00006 | C7: 包益民 | D7: YIMIN.BAO | E7: YIMIN BAO | F7: =VLOOKUP(D7,Sheet2!$B$1:$B$558,1,FALSE) -> yimin.bao | G7: 上海研发中心 | H7: 车辆性能及底盘设计
A8: 7 | B8: E00007 | C8: 徐兵 | D8: BING.XU | E8: BING XU | F8: =VLOOKUP(D8,Sheet2!$B$1:$B$558,1,FALSE) -> Bing.Xu | G8: 信息技术管理中心 | H8: -
A9: 8 | B9: E00050 | C9: 金亨珍 | D9: HyungJin.Kim | E9: KIM HYUNG JIN | F9: =VLOOKUP(D9,Sheet2!$B$1:$B$558,1,FALSE) -> HyungJin.Kim | G9: 上海研发中心 | H9: 车身工程
A10: 9 | B10: E00053 | C10: 崔宇值 | D10: Stan.Choi | E10: CHOI WOOSIK | F10: =VLOOKUP(D10,Sheet2!$B$1:$B$558,1,FALSE) -> Stan.Choi | G10: 上海研发中心 | H10: 车身工程
A11: 10 | B11: E00108 | C11: 梁圣哲 | D11: Sungchul.Yang | E11: YANG SUNG CHUL | F11: =VLOOKUP(D11,Sheet2!$B$1:$B$558,1,FALSE) -> Sungchul.Yang | G11: 上海研发中心 | H11: 车身工程
A12: 11 | B12: E00115 | C12: 张太永 | D12: TaeYoung.Chang | E12: CHANG TAE-YOUNG | F12: =VLOOKUP(D12,Sheet2!$B$1:$B$558,1,FALSE) -> TaeYoung.Chang | G12: 上海研发中心 | H12: 车身工程
A13: 12 | B13: E00122 | C13: 鞠重男 | D13: John.Kook | E13: KOOK JUNG NAM | F13: =VLOOKUP(D13,Sheet2!$B$1:$B$558,1,FALSE) -> John.Kook | G13: 上海研发中心 | H13: 电子电器
A14: 13 | B14: E00123 | C14: 崔裕硕 | D14: Brian.Choi | E14: CHOI YOU SEOK | F14: =VLOOKUP(D14,Sheet2!$B$1:$B$558,1,FALSE) -> Brian.Choi | G14: 上海研发中心 | H14: 电子电器
... A454: 461 | B454: A0020 | C454: 雍慧慧 | D454: Huihui.Yong | E454: Huihui Yong | F454: =VLOOKUP(D454,Sheet2!$B$1:$B$558,1,FALSE) -> Huihui.Yong | G454: 公司管理中心 | H454: 人力资源/行政管理部

Sheet Sheet2
A1: Display Name | B1: SAM Account Name
A2: Aaron Smith | B2: Aaron.Smith
A3: Aifeng Lu (陆爱峰) | B3: aifeng.lu
A4: Allan Hoffman | B4: allan.hoffman
A5: Andre Thompson | B5: Andre.Thompson
A6: Anthony Marcheff | B6: Anthony.Marcheff
A7: Anwar Mohammad | B7: anwar.mohammad
A8: Aodong Chen (陈傲东) | B8: Aodong.Chen
A9: Baiwen Li (李柏文) | B9: Baiwen.Li
A10: Baohua Zhu (朱保华) | B10: Baohua.Zhu
A11: Beibei Wang (王贝贝) | B11: Beibei.Wang
A12: Biao Ma (马彪) | B12: Biao.Ma
... A557: Zudeng Yu (余祖登) | B557: Zudeng.Yu

Sheet Persons
A1: 工号 | B1: 中文名 | C1: 英文名 | D1: 职位 | E1: 电话 | F1: 成本中心 | G1: Division(二级部门) | H1: Department(三级部门)
